Workbook
Name \f: #REF!
Name \M: #REF!
Name ________________QB156: #REF!
Name ________________Ri3: #REF!
Name ________________ZZ13: #REF!
Name _______________QB156: #REF!
Name _______________Ri3: #REF!
Name _______________ZZ13: #REF!
Name ______________QB156: #REF!
Name ______________Ri3: #REF!
Name ______________ZZ13: #REF!
Name _____________D72000: #REF!
Name _____________QB156: #REF!
Name _____________Ri3: #REF!
Name _____________ZZ13: #REF!
Name ____________D72000: #REF!
Name ____________QB156: #REF!
Name ____________Ri3: #REF!
Name ____________ZZ13: #REF!
Name ___________D72000: #REF!
Name ___________QB156: #REF!
Name ___________Ri3: #REF!
Name ___________ZZ13: #REF!
Name __________QB156: #REF!
Name __________Ri3: #REF!
Name __________ZZ13: #REF!
Name _________D72000: #REF!
Name _________QB156: #REF!
Name _________Ri3: #REF!
Name _________ZZ13: #REF!
Name ________D72000: #REF!
Name ________QB156: #REF!
Name ________Ri3: #REF!
Name ________RZ16: #REF!
Name ________Sum1: #REF!
Name ________Sum2: #REF!
Name ________Sum3: #REF!
Name ________ZZ13: #REF!
Name _______D72000: #REF!
Name _______QB156: #REF!
Name _______Ri3: #REF!
Name _______RZ16: #REF!
Name _______Sum1: #REF!
Name _______Sum2: #REF!
Name _______Sum3: #REF!
Name _______ZZ13: #REF!
Name ______D72000: #REF!
Name ______QB156: #REF!
Name ______Ri3: #REF!
Name ______RZ16: #REF!
Name ______Sum1: #REF!
Name ______Sum2: #REF!
Name ______Sum3: #REF!
Name ______ZZ13: #REF!
Name _____D72000: #REF!
Name _____QB156: #REF!
Name _____Ri3: #REF!
Name _____RZ16: #REF!
Name _____Sum1: #REF!
Name _____Sum2: #REF!

Sheet CPM DATA
B2: Cost Per Minute (Sewing Based)
B4: Description | C4: 46023 | D4: 46054 | E4: 46082 | F4: 46113 | G4: 46143 | H4: 46174 | I4: Monthly Average | J4: CPM @ 100%
B5: Sewing Available Minutes | C5: 5777756 | D5: 6170709 | E5: 5825304.8 | F5: 6987241 | G5: 6388000.9 | H5: 6536735 | I5: =IFERROR(AVERAGE(G5:H5),0) -> 6462368 | J5: =+I5 -> 6462368
B6: Sewing Utilized Minutes | C6: 3140509 | D6: 3519579 | E6: 2739816.2 | F6: 3281077.8 | G6: 3110908.3 | H6: 3369625 | I6: =IFERROR(AVERAGE(G6:H6),0) -> 3240266.6
B7: Efficiency Achieved | C7: =C6/C5 -> 0.54355168 | D7: =D6/D5 -> 0.57036866 | E7: =E6/E5 -> 0.4703301 | F7: =F6/F5 -> 0.46958131 | G7: =G6/G5 -> 0.48699245 | H7: =H6/H5 -> 0.51549053 | I7: =I6/I5 -> 0.50140547
B12: Labour Cost | AQ12: RENT | AR12: 8495000 | AS12: 8495000 | AT12: 8567000 | AU12: =AVERAGE(AR12:AT12) -> 8519000
A13: Direct Labour | B13: Total Direct Labour | C13: 49680298 | D13: 47609621 | E13: 46947336 | F13: 44804053 | G13: 54970275 | H13: 60499711 | I13: =IFERROR(AVERAGE(G13:H13),0) -> 57734993 | J13: =I13/J$5 -> 8.9340306
AQ14: SALARIES | AR14: 44420634 | AS14: 43814024 | AT14: 44489280 | AU14: =AVERAGE(AR14:AT14) -> 44241313
B15: Fixed Cost Break-up | AQ15: RENT | AR15: 8495000 | AS15: 8495000 | AT15: 8567000 | AU15: =AVERAGE(AR15:AT15) -> 8519000
A16: Salaries | B16: Salaries and Wages | C16: =128179306-C13 -> 78499008 | D16: =128918111-D13 -> 81308490 | E16: =127120363-E13 -> 80173027 | F16: =126398901-F13 -> 81594848 | G16: =137198675-G13 -> 82228400 | H16: =139945709.35-H13 -> 79445998 | I16: =IFERROR(AVERAGE(G16:H16),0) -> 80837199 | J16: =I16/J$5 -> 12.508913 | AQ16: TRAVELLING EXPENSE | AR16: 3730907 | AS16: 2356997 | AT16: 2911108 | AU16: =AVERAGE(AR16:AT16) -> 2999670.7
I17: =IFERROR(AVERAGE(G17:H17),0) -> 0 | J17: =I17/J$5 -> 0
B18: Factory Over Heads | I18: =IFERROR(AVERAGE(G18:H18),0) -> 0 | J18: =I18/J$5 -> 0
A19: R&M | B19: Repair & maintenance | C19: 3022366.1 | D19: 3022366.1 | E19: 1042959.6 | F19: 3075213.1 | G19: 772708 | H19: 1723624.2 | I19: =IFERROR(AVERAGE(G19:H19),0) -> 1248166.1 | J19: =I19/J$5 -> 0.19314377
A20: Utility Cost | B20: Utilities & Power | C20: 16337039 | D20: 20894600 | E20: 17610910 | F20: 21117289 | G20: 21857448 | H20: 24110002 | I20: =IFERROR(AVERAGE(G20:H20),0) -> 22983725 | J20: =I20/J$5 -> 3.5565485
A21: FOH/Admin | B21: Rent, rates & taxes | C21: 9908325 | D21: 9908325 | E21: 10268325 | F21: 9908325 | G21: 10268325 | H21: 12260025 | I21: =IFERROR(AVERAGE(G21:H21),0) -> 11264175 | J21: =I21/J$5 -> 1.7430414
A22: Depreciation | B22: Depreciation - owned assets | C22: 6894145.8 | D22: 6841152.9 | E22: 6852029.4 | F22: 6797089.8 | G22: 6838803.9 | H22: 6791195.6 | I22: =IFERROR(AVERAGE(G22:H22),0) -> 6814999.8 | J22: =I22/J$5 -> 1.054567
I23: =IFERROR(AVERAGE(G23:H23),0) -> 0 | J23: =I23/J$5 -> 0
A24: FOH/Admin | B24: Rent Expenses | C24: 1100925 | D24: 1100925 | E24: 1140925 | F24: 1100925 | G24: 1140925 | H24: 1362225 | I24: =IFERROR(AVERAGE(G24:H24),0) -> 1251575 | J24: =I24/J$5 -> 0.19367127
A25: R&M | B25: Repair & Maintenance | C25: 297841.1 | D25: 335818.45 | E25: 115884.4 | F25: 341690.34 | G25: 85856.444 | H25: 191513.8 | I25: =IFERROR(AVERAGE(G25:H25),0) -> 138685.12 | J25: =I25/J$5 -> 0.021460419
A26: Utility Cost | B26: Utility Expenses | C26: 1815226.6 | D26: 2322049.8 | E26: 1862984.7 | F26: 2164807.4 | G26: 2428605.3 | H26: 2649916.9 | I26: =IFERROR(AVERAGE(G26:H26),0) -> 2539261.1 | J26: =I26/J$5 -> 0.39293044
A27: FOH/Admin | B27: Travel & Accommodation (Fuel +Car Allowances) | C27: 6911305.3 | D27: 5153138.8 | E27: 10052441 | F27: 5504482 | G27: 6818304 | H27: 5177364 | I27: =IFERROR(AVERAGE(G27:H27),0) -> 5997834 | J27: =I27/J$5 -> 0.92811707
A28: FOH/Admin | B28: Transportation Expense A/C | F28: 2568541 | G28: 3692636.3 | H28: 3575280.6 | I28: =IFERROR(AVERAGE(G28:H28),0) -> 3633958.5 | J28: =I28/J$5 -> 0.56232615
A29: FOH/Admin | B29: Foreign Travelling | F29: 5309275 | G29: 1269000 | H29: 2902284 | I29: =IFERROR(AVERAGE(G29:H29),0) -> 2085642 | J29: =I29/J$5 -> 0.3227365
A30: FOH/Admin | B30: Insurance Expenses | C30: 2301142 | D30: 2548486 | E30: 2796310 | F30: 1531767 | G30: 1328981 | H30: 1547789 | I30: =IFERROR(AVERAGE(G30:H30),0) -> 1438385 | J30: =I30/J$5 -> 0.22257863
A31: FOH/Admin | B31: Legal Expenses | C31: -237765.99 | D31: 5512909 | E31: 3893277 | F31: 2956490 | G31: 3663302.4 | H31: 3158634 | I31: =IFERROR(AVERAGE(G31:H31),0) -> 3410968.2 | J31: =I31/J$5 -> 0.52782017
A32: FOH/Admin | B32: Entertainment - Staff / Canteen / Worker Welfar exp | C32: 2438000 | D32: 1820454 | E32: 3336810 | F32: 2637527 | G32: 2881212 | H32: 2460613 | I32: =IFERROR(AVERAGE(G32:H32),0) -> 2670912.5 | J32: =I32/J$5 -> 0.41330245
A33: FOH/Admin | B33: Entertainment Expenses | I33: =IFERROR(AVERAGE(G33:H33),0) -> 0 | J33: =I33/J$5 -> 0
A34: FOH/Admin | B34: Head Office Expenses | C34: 5470308 | D34: 3842211 | E34: 5074045 | F34: 5888985 | G34: 4255840 | H34: 4834034 | I34: =IFERROR(AVERAGE(G34:H34),0) -> 4544937 | J34: =I34/J$5 -> 0.70329282
A35: FOH/Admin | B35: USA Office Exp | C35: 324795 | D35: 4287477 | E35: 3249370 | F35: 3723791 | G35: 3839552 | H35: 4417631 | I35: =IFERROR(AVERAGE(G35:H35),0) -> 4128591.5 | J35: =I35/J$5 -> 0.63886667
A36: Depreciation | B36: Depreciation Expenses | C36: 766016.2 | D36: 760128.1 | E36: 761336.6 | F36: 755232.2 | G36: 759867.1 | H36: 754577.29 | I36: =IFERROR(AVERAGE(G36:H36),0) -> 757222.2 | J36: =I36/J$5 -> 0.11717411
A37: FOH/Admin | B37: Loading and unloading exp | C37: 924405 | D37: 564460 | E37: 796157 | F37: 574518.01 | G37: 1483200 | H37: 1458954 | I37: =IFERROR(AVERAGE(G37:H37),0) -> 1471077 | J37: =I37/J$5 -> 0.22763746
A38: FOH/Admin | B38: Testing & Compliance | C38: 218913.7 | D38: 1397836.8 | E38: 868501.2 | F38: 1542399.5 | G38: 694687.86 | H38: 1271047.6 | I38: =IFERROR(AVERAGE(G38:H38),0) -> 982867.76 | J38: =I38/J$5 -> 0.15209096
A39: FOH/Admin | B39: Washing | I39: =IFERROR(AVERAGE(G39:H39),0) -> 0 | J39: =I39/J$5 -> 0
A40: FOH/Admin | B40: Other Expenses | C40: 1568877 | D40: 2813033 | E40: 3631180 | F40: 1825585 | G40: 384500 | H40: 1516879 | I40: =IFERROR(AVERAGE(G40:H40),0) -> 950689.5 | J40: =I40/J$5 -> 0.14711163
A41: R&M | B41: General Overheads | C41: 9315347 | D41: 8194932 | E41: 4459707 | F41: 6239504 | G41: 4966267 | H41: 7084917 | I41: =IFERROR(AVERAGE(G41:H41),0) -> 6025592 | J41: =I41/J$5 -> 0.9324124
A42: FOH/Admin | B42: Computer & It Expenses | C42: 11050 | D42: 21700 | E42: 19000 | F42: 258150 | G42: 33100 | H42: 255550 | I42: =IFERROR(AVERAGE(G42:H42),0) -> 144325 | J42: =I42/J$5 -> 0.022333145
A43: FOH/Admin | B43: Communication Expenses | C43: 527200 | D43: 126542 | E43: 715487 | F43: 715251 | G43: 624878 | H43: 155930 | I43: =IFERROR(AVERAGE(G43:H43),0) -> 390404 | J43: =I43/J$5 -> 0.060411911
A44: FOH/Admin | B44: Printing & Stationary | C44: 17000 | D44: 16050 | E44: 0 | F44: 2000 | G44: 20600 | H44: 21400 | I44: =IFERROR(AVERAGE(G44:H44),0) -> 21000 | J44: =I44/J$5 -> 0.0032495828
B46: Overheads Total | C46: =SUM(C16:C45) -> 1.4843147e+08 | D46: =SUM(D16:D45) -> 1.6279308e+08 | E46: =SUM(E16:E45) -> 1.5872067e+08 | F46: =SUM(F16:F45) -> 1.6813369e+08 | G46: =SUM(G16:G45) -> 1.62337e+08 | H46: =SUM(H16:H45) -> 1.6912739e+08 | I46: =SUM(I16:I45) -> 1.6573219e+08 | J46: =SUM(J16:J45) -> 25.645737
B49: Total Factory Cost | C49: =C46+C13 -> 1.9811177e+08 | D49: =D46+D13 -> 2.1040271e+08 | E49: =E46+E13 -> 2.05668e+08 | F49: =F46+F13 -> 2.1293774e+08 | G49: =G46+G13 -> 2.1730727e+08 | H49: =H46+H13 -> 2.296271e+08 | I49: =I46+I13 -> 2.2346719e+08 | J49: =I49/J$5 -> 34.579768
...

Sheet Smy
B3: Customers | C3: Pcs | D3: FOH/Pcs | E3: FOH | F3: Direct Cost/Pcs | G3: Direct Cost | H3: SAM | I3: Eff. | J3: Total Cost | K3: Cost/Pcs
B4: Duer | C4: 80000 | D4: 1232.5638 | E4: =D4*C4 -> 98605107 | F4: 580 | G4: =F4*C4 -> 46400000 | H4: 26 | I4: 0.47 | J4: =G4+E4 -> 1.4500511e+08 | K4: =J4/C4 -> 1812.5638
B5: Zara | C5: 50000 | D5: 515.46502 | E5: =D5*C5 -> 25773251 | F5: 251 | G5: =F5*C5 -> 12550000 | H5: 18 | I5: 0.75 | J5: =G5+E5 -> 38323251 | K5: =J5/C5 -> 766.46502
B6: Mustang & Others | C6: 40000 | D6: 1030.93 | E6: =D6*C6 -> 41237201 | F6: 503 | G6: =F6*C6 -> 20120000 | H6: 24 | I6: 0.5 | J6: =G6+E6 -> 61357201 | K6: =J6/C6 -> 1533.93
B7: total | C7: =SUM(C4:C6) -> 170000 | D7: =SUMPRODUCT($D$4:$D$6,$C$4:$C$6)/$C$7 -> 974.20917 | E7: =SUM(E4:E6) -> 1.6561556e+08 | F7: =SUMPRODUCT($F$4:$F$6,$C$4:$C$6)/$C$7 -> 465.11765 | G7: =SUM(G4:G6) -> 79070000 | H7: =SUMPRODUCT($H$4:$H$6,$C$4:$C$6)/$C$7 -> 23.176471 | I7: =SUMPRODUCT($I$4:$I$6,$C$4:$C$6)/$C$7 -> 0.55941176 | J7: =SUM(J4:J6) -> 2.4468556e+08 | K7: =SUMPRODUCT($K$4:$K$6,$C$4:$C$6)/$C$7 -> 1439.3268
H9: =+H7*200000 -> 4635294.1 | J9: 12000000
J10: 200000000
H11: =+J10/H9 -> 43.147208
H12: =+H11/278 -> 0.15520578

Sheet Listing
A3: Customer | C3: Order Type | E3: Style Category | G3: Wash Type : | I3: Inhouse/Sub-contract | K3: Costing Stage | M3: Payment Terms
A4: RETROJEANS | C4: Denim | E4: Men's Pant | G4: Dyeing | I4: INHOUSE | K4: Quote | M4: LC at Sight
A5: Miniconf | C5: Non Denim | E5: Ladies Pant | G5: EW/Biopolish | I5: CMT | K5: Final | M5: LC-30 days
A6: RETROJEANS | E6: Shorts | G6: EW/Bleach | M6: LC-45 days
A7: Duer | E7: Top Ware | G7: EW/Caustic | I7: Shipment mode | K7: Delivery terms | M7: LC-60 days
A8: MUSTANG | E8: Shirt | G8: Stone Bleach | I8: Sea | K8: FOB | M8: LC-75 days
A9: MOHITO | E9: Boys Pant | G9: Stone Caustic | I9: Air | K9: DDP/LDP | M9: DA
A10: FQ1924 | E10: Girls Pant | G10: Stone Wash | K10: CIF | M10: LC-90 days
A11: CASUAL FRIDAY | E11: Kid's Pant | G11: Pinky Random | I11: Delv. Distination | K11: CFR | M11: LC-120 days
A12: Pulz Jeans | G12: Bleach Random | I12: EURO | M12: Advance
A13: B4 Kids | G13: Snow Random | I13: USA
A14: BLUECRAFT | G14: Rinse
A15: STOOKER | G15: Rinse/Softner
A16: DR DENIM | G16: Softner
A17: UNITED BRANDS | G17: Silicon Ball
A18: Blend
A19: FRANSA
A20: LOIS
A21: OVER/D
A22: SOLID
A23: DK COMPANY VEJLE A/S
A24: Zara

Sheet Style Wise Summary
B3: Style Name | C3: Customer Name | D3: Style Category | E3: Wash Type | F3: Order Quantity | G3: Order Size | H3: SMV | I3: Rejection % | J3: Avg. Efficiency | K3: Selling Price | L3: Selling Expenses | M3: Net Price | N3: Fabric Code | O3: Fabric Con. | P3: Fabric Rate | Q3: Fabric Cost | R3: Lining Code | S3: Lining Cost | T3: Accessories Cost | U3: Chemical Cost | V3: Other Cost | W3: D Labor Cost | X3: Utilities Cost | Y3: Leftover Factor | Z3: Total Material Cost | AA3: CM/Pc | AB3: Total OH Cost | AC3: EBITDA | AD3: Order FOB/PC | AE3: Target FOB/PC | AF3: Order CM/PC | AG3: Target CM/SMV-Cents | AH3: Order CM-SMV-Cents
B4: =Model!$D$8 -> TR 298 VITA | C4: =Model!$D$6 -> Duer | D4: =Model!$D$9 -> Top Ware | E4: =Model!$D$14 -> Rinse | F4: =Model!$D$11 -> 219 | G4: =Model!$D$10 -> <=500 | H4: =Model!$J$11 -> 28.47 | I4: =Model!$D$15 -> 0.0415 | J4: =Model!$J$13 -> 0.47 | K4: =Model!$E$20 -> 22.9 | L4: =SUM(Model!$E$23:$E$28)+Model!$E$21 -> 1.0534 | M4: =Model!$E$29 -> 21.8466 | N4: =Model!$J$20 -> FVG0562 Black IAF-3605 | O4: =Model!$K$26 -> 1.35 | P4: =Model!$M$26 -> 3.6546763 | Q4: =Model!$E$32 -> 4.9338129 | R4: =Model!$J$28 -> IAF-34663%4% 65:35 PC | S4: =Model!$E$33 -> 0.077338129 | T4: =Model!$E$34 -> 8.2014388 | U4: =Model!$E$35 -> 0.089928058 | V4: =Model!$E$36 -> 0 | W4: =Model!$E$37 -> 1.9466696 | X4: =Model!$E$38 -> 0.97718068 | Y4: =Model!$E$39 -> 0.67339428 | Z4: =Q4+S4+T4+U4+V4+W4+X4+Y4 -> 16.899763 | AA4: =Model!$E$42 -> 4.9468374 | AB4: =Model!$E$50 -> 4.4891437 | AC4: =Model!$E$53 -> 0.45769374 | AD4: =Model!$J$6 -> 22.9 | AE4: =Model!$J$5 -> 25.357665 | AF4: =Model!$J$7 -> 4.9468374 | AG4: =Model!$J$8 -> 12.037167 | AH4: =Model!$J$9 -> 8.1665388
B6: TR 298 VITA | C6: B4 Kids | D6: Top Ware | E6: Softner | F6: 2000 | G6: 1001-2000 | H6: 24 | I6: 0.0315 | J6: 0.5 | K6: 13.79 | L6: 0.5516 | M6: 13.2384 | N6: FVG0562 Black IAF-3605 | O6: 1.26 | P6: 3.62 | Q6: 4.5612 | R6: IAF-34663%4% 65:35 PC | S6: 0.219096 | T6: 0.85 | U6: 0.32335689 | V6: 0 | W6: 1.2916702 | X6: 0.5175943 | Y6: 0.2445319 | Z6: 8.0074493 | AA6: 5.2309507 | AB6: 3.7083814 | AC6: 1.5225693 | AD6: 13.79 | AE6: 13.805801 | AF6: 5.2309507 | AG6: 10.929417 | AH6: 10.897814

Sheet Reject Grid
C2: PROPOSED REJECTION %
B4: Fabric | C4: Category | D4: <=500 | E4: 501-1000 | F4: 1001-2000 | G4: 2001-3000 | H4: 3001-4000 | I4: 4001-5000 | J4: 5001-10000 | K4: 10001-25000 | L4: >25000
C5: Basic | E5: 0.5 | F5: 0.48 | G5: 0.46 | H5: 0.44 | I5: 0.42 | J5: 0.4 | K5: 0.38 | L5: 0.36
C6: Semi Fashion | E6: 0.7 | F6: 0.67 | G6: 0.64 | H6: 0.61 | I6: 0.58 | J6: 0.55 | K6: 0.52 | L6: 0.49
C7: Fashion | E7: 0.85 | F7: 0.81 | G7: 0.77 | H7: 0.73 | I7: 0.69 | J7: 0.65 | K7: 0.61 | L7: 0.57
C8: High Fashion
B10: Cutting | C10: Category | D10: <=500 | E10: 501-1000 | F10: 1001-2000 | G10: 2001-3000 | H10: 3001-4000 | I10: 4001-5000 | J10: 5001-10000 | K10: 10001-25000 | L10: >25000
C11: Basic | E11: 0.25 | F11: 0.23 | G11: 0.21 | H11: 0.19 | I11: 0.17 | J11: 0.15 | K11: 0.13 | L11: 0.11
C12: Semi Fashion | E12: 0.35 | F12: 0.32 | G12: 0.29 | H12: 0.26 | I12: 0.23 | J12: 0.2 | K12: 0.17 | L12: 0.14
C13: Fashion | E13: 0.45 | F13: 0.41 | G13: 0.37 | H13: 0.33 | I13: 0.29 | J13: 0.25 | K13: 0.21 | L13: 0.17
C14: High Fashion
B16: Sewing | C16: Category | D16: <=500 | E16: 501-1000 | F16: 1001-2000 | G16: 2001-3000 | H16: 3001-4000 | I16: 4001-5000 | J16: 5001-10000 | K16: 10001-25000 | L16: >25000
C17: Basic | E17: 0.5 | F17: 0.48 | G17: 0.46 | H17: 0.44 | I17: 0.42 | J17: 0.4 | K17: 0.38 | L17: 0.36
C18: Semi Fashion | E18: 0.75 | F18: 0.72 | G18: 0.69 | H18: 0.66 | I18: 0.63 | J18: 0.6 | K18: 0.57 | L18: 0.54
C19: Fashion | E19: 1 | F19: 0.96 | G19: 0.92 | H19: 0.88 | I19: 0.84 | J19: 0.8 | K19: 0.76 | L19: 0.72
C20: High Fashion
C21: Extreme Fashion
C22: Top Wears
B24: Finishing | C24: Category | D24: <=500 | E24: 501-1000 | F24: 1001-2000 | G24: 2001-3000 | H24: 3001-4000 | I24: 4001-5000 | J24: 5001-10000 | K24: 10001-25000 | L24: >25000
C25: Basic | E25: 0.25 | F25: 0.24 | G25: 0.23 | H25: 0.22 | I25: 0.21 | J25: 0.2 | K25: 0.19 | L25: 0.18
C26: Semi Fashion | E26: 0.35 | F26: 0.33 | G26: 0.31 | H26: 0.29 | I26: 0.27 | J26: 0.25 | K26: 0.23 | L26: 0.21
C27: Fashion | E27: 0.45 | F27: 0.42 | G27: 0.39 | H27: 0.36 | I27: 0.33 | J27: 0.3 | K27: 0.27 | L27: 0.24
C28: High Fashion
C29: Extreme Fashion
C30: Top Wears
B32: Washing | C32: Wash Types | D32: <=500 | E32: 501-1000 | F32: 1001-2000 | G32: 2001-3000 | H32: 3001-4000 | I32: 4001-5000 | J32: 5001-10000 | K32: 10001-25000 | L32: >25000 | M32: {=SUM(IF('Reject Grid'!$D$32:$L$32=Model!$D$10,IF('Reject Grid'!$C$33:$C$46=Model!$D$14,'Reject Grid'!$D$33:$L$46)))} -> 1
C33: Dyeing | D33: 1.5 | E33: 1 | F33: 1 | G33: 1 | H33: 1 | I33: 0.9 | J33: 0.9 | K33: 0.75 | L33: 0.75
C34: EW/Biopolish | D34: 1.5 | E34: 1 | F34: 1 | G34: 0.75 | H34: 0.75 | I34: 0.9 | J34: 0.9 | K34: 0.75 | L34: 0.75
C35: EW/Bleach | D35: 1.5 | E35: 1.35 | F35: 1.35 | G35: 1 | H35: 1 | I35: 0.9 | J35: 0.9 | K35: 0.75 | L35: 0.75
C36: EW/Caustic | D36: 1.5 | E36: 1.35 | F36: 1.35 | G36: 1 | H36: 1 | I36: 0.9 | J36: 0.9 | K36: 0.75 | L36: 0.75
C37: Stone Bleach | D37: 1.5 | E37: 1.35 | F37: 1.35 | G37: 1 | H37: 1 | I37: 0.9 | J37: 0.9 | K37: 0.75 | L37: 0.75
C38: Stone Caustic | D38: 1.5 | E38: 1.35 | F38: 1.35 | G38: 1 | H38: 1 | I38: 0.9 | J38: 0.9 | K38: 0.75 | L38: 0.75
C39: Stone Wash | D39: 1.5 | E39: 1.35 | F39: 1.35 | G39: 1 | H39: 1 | I39: 0.9 | J39: 0.9 | K39: 0.75 | L39: 0.75
C40: Pinky Random | D40: 1.5 | E40: 1.5 | F40: 1.5 | G40: 1.5 | H40: 1.5 | I40: 1.35 | J40: 1.35 | K40: 1.35 | L40: 1.35
C41: Bleach Random | D41: 1.5 | E41: 1.5 | F41: 1.5 | G41: 0.015 | H41: 0.015 | I41: 1.35 | J41: 1.35 | K41: 1.35 | L41: 1.35
C42: Snow Random | D42: 1.5 | E42: 1.5 | F42: 1.5 | G42: 0.015 | H42: 0.015 | I42: 1.35 | J42: 1.35 | K42: 1.35 | L42: 1.35
C43: Rinse | D43: 1 | E43: 1 | F43: 1 | G43: 0.7 | H43: 0.7 | I43: 0.7 | J43: 0.7 | K43: 0.65 | L43: 0.65
C44: Rinse/Softner | D44: 1 | E44: 1 | F44: 1 | G44: 0.7 | H44: 0.7 | I44: 0.7 | J44: 0.7 | K44: 0.65 | L44: 0.65
... C46: Silicon Ball | D46: 1 | E46: 1 | F46: 1 | G46: 0.7 | H46: 0.7 | I46: 0.7 | J46: 0.7 | K46: 0.65 | L46: 0.65
B48: WIP | C48: Category | D48: <=500 | E48: 501-1000 | F48: 1001-2000 | G48: 2001-3000 | H48: 3001-4000 | I48: 4001-5000 | J48: 5001-10000 | K48: 10001-25000 | L48: >25000
...

Sheet Model
C3: Indus Plus (Pvt) Ltd.
C4: Pre Order Cost Sheet
C5: Costing Date(mm/dd/yy) | D5: =TODAY() -> 46228 | F5: Current Date | G5: =TODAY() -> 46228 | I5: Target FOB/PC | J5: =((E20-E56)+(E20-E56-J6)*(O12+O13+O14+S5))/90%*100% -> 25.357665 | K5: EBITDA/Min-Cents | O5: =($O$6*$J$13/$J$11)/(1+$D$15)*100 -> 0.72548108
C6: Customer Name: | D6: Duer | F6: Costing Stage | G6: Quote | I6: Order FOB/PC | J6: 22.9 | K6: EBITDA/PC | O6: =E53 -> 0.45769374
C7: Order Type | D7: Denim | F7: Country | G7: SPAIN | I7: Order CM/PC | J7: =(J6)-((SUM(E21:E28)+E40)) -> 4.9468374 | K7: Net Profit/Min-Cents | O7: =($O$8*$J$13/$J$11)*100 -> 0.12326488
C8: Style | D8: TR 298 VITA | F8: Payment Terms | G8: Days | I8: Target CM/SMV-Cents | J8: =((J5-(J5*SUM(O12:O14)))-E40)*(J13/J11)*100 -> 12.037167 | K8: Net Profit/PC | O8: =E56 -> 0.074667045
C9: Style Category | D9: Top Ware | F9: LC-60 days | I9: Order CM-SMV-Cents | J9: =($J$7*$J$13/$J$11)*100 -> 8.1665388 | K9: Net Profit % on FOB | O9: =G56 -> 0.0034177879
C10: Order Size | D10: =IF($D$11>=125000,"Capacity Qty",IF(AND(D11<=500),"<=500",IF(AND(D11>500,D11<=1000),"501-1000",IF(AND(D11>1000,D11<=2000),"1001-2000",IF(AND(D11>2000,D11<=3000),"2001-3000",IF(AND(D11>3000,D11<=4000),"3001-4000",IF(AND(D11>4000,D11<=5000),"4001-5000",IF(AND(D11>5000,D11<=10000),"5001-10000",IF(AND(D11>10000,D11<=25000),"10001-25000",IF(D11>25000,">25000")))))))))) -> <=500 | F10: DA
C11: Order Quantity pcs | D11: 219 | F11: Shipment mode | G11: Sea | I11: SMV | J11: 28.47 | K11: Commission % | O11: 0
C12: Per Color Quantity pcs | D12: =+D11/D13 -> 219 | F12: Delivery terms | G12: FOB | I12: Manpower Per Line | J12: 60 | K12: Tax & EDS | O12: 0.025
C13: No of Color | D13: 1 | F13: Merch_Group | G13: Ayaz | I13: Avg. Efficiency | J13: ='Master Grid'!G67 -> 0.47 | K13: Inland Freight & Clearing | O13: =IF($D$6="Duer",1.25%,0.65%) -> 0.0125
C14: Wash Type : | D14: Rinse | F14: Delv. Distination | G14: EURO | K14: Local Bank Charges | O14: 0.0085
C15: Rejection % | D15: ='Master Grid'!N77% -> 0.0415 | F15: Parity-Sale | G15: 278 | I15: Avg. Line Target | J15: =($J$12*480/$J$11)*$J$13 -> 475.44784 | K15: Discount Rate | O15: 0.12
C16: Ex fty Date(mm/dd/yy) | D16: 46112 | F16: Parity-Procurement | G16: 278
F17: Inhouse/Sub-contract | G17: INHOUSE
D19: Rs | E19: $ | G19: % | I19: Fabric | J19: Item Name | K19: Cons. / Pc | L19: UOM | M19: Rate-$ | N19: Rate-Pkr | O19: Cost
C20: Selling Price | D20: =J6*$G$15 -> 6366.2 | E20: =D20/$G$15 -> 22.9 | I20: Fabric_1 | J20: FVG0562 Black IAF-3605 | K20: 1.35 | L20: Mtr | M20: 3.6546763 | N20: =M20*$G$16 -> 1016 | O20: =K20*N20 -> 1371.6
C21: Tax & EDS | D21: =D20*O12 -> 159.155 | E21: =D21/$G$15 -> 0.5725 | G21: =E21/E$20 -> 0.025 | I21: Fabric_2 | N21: =M21*$G$16 -> 0 | O21: =K21*N21 -> 0
C22: Rebate (add) | E22: =D22/$G$15 -> 0 | G22: =E22/E$20 -> 0 | I22: Fabric_2 | N22: =M22*$G$16 -> 0 | O22: =K22*N22 -> 0
C23: Comm | D23: =O11*D20 -> 0 | E23: =D23/$G$15 -> 0 | G23: =E23/E$20 -> 0 | I23: Fabric_3 | N23: =M23*$G$16 -> 0 | O23: =K23*N23 -> 0
C24: Inland Freight & Clearing | D24: =$D$20*O13 -> 79.5775 | E24: =D24/$G$15 -> 0.28625 | G24: =E24/E$20 -> 0.0125 | I24: Fabric_4 | N24: =M24*$G$16 -> 0
C25: Markup and Discounting | D25: =($D$20/365*$O$15*G$9) -> 0 | E25: =D25/$G$15 -> 0 | G25: =E25/E$20 -> 0 | I25: Fabric_5 | N25: =M25*$G$16 -> 0 | O25: =K25*N25 -> 0
C26: Local Bank Charges | D26: =$D$20*O14 -> 54.1127 | E26: =D26/$G$15 -> 0.19465 | G26: =E26/E$20 -> 0.0085 | I26: Total | K26: =SUM(K20:K25) -> 1.35 | M26: {=SUMPRODUCT($M$20:$M$25,$K$20:$K$25/$K$26)} -> 3.6546763 | N26: {=SUMPRODUCT($N$20:$N$25,$K$20:$K$25/$K$26)} -> 1016 | O26: =SUM(O20:O25) -> 1371.6
C27: Factoring | D27: =($D$20/365*$O$15*G$10) -> 0 | E27: =D27/$G$15 -> 0 | G27: =E27/E$20 -> 0 | I27: Pocket Lining | J27: Item Name | K27: Cons. / Pc | L27: UOM | M27: Rate-$ | N27: Rate-Pkr | O27: Cost
C28: Foreign B Ch & Oth | D28: 0 | E28: =D28/$G$15 -> 0 | G28: =E28/E$20 -> 0 | I28: Lining_1 | J28: IAF-34663%4% 65:35 PC | K28: 0.1 | L28: Mtr | M28: 0.77338129 | N28: =M28*$G$16 -> 215 | O28: =K28*N28 -> 21.5
C29: Net Price | D29: =D20-D21+D22-SUM(D23:D28) -> 6073.3548 | E29: =E20-E21+E22-SUM(E23:E28) -> 21.8466 | G29: =E29/E$20 -> 0.954 | I29: Lining_2 | N29: =M29*$G$16 -> 0 | O29: =K29*N29 -> 0
I30: Lining_3 | N30: =M30*$G$16 -> 0 | O30: =K30*N30 -> 0
C31: Material Cost | D31: Rs | E31: $ | I31: Lining_4 | N31: =M31*$G$16 -> 0
C32: Fabric | D32: =O26 -> 1371.6 | E32: =D32/$G$15 -> 4.9338129 | G32: =E32/E$29 -> 0.22583894 | I32: Lining_5 | N32: =M32*$G$16 -> 0 | O32: =K32*N32 -> 0
C33: Linning | D33: =O33 -> 21.5 | E33: =D33/$G$15 -> 0.077338129 | G33: =E33/E$29 -> 0.0035400533 | I33: Total | K33: =SUM(K28:K32) -> 0.1 | M33: {=SUMPRODUCT($M$28:$M$32,$K$28:$K$32/$K$33)} -> 0.77338129 | N33: {=SUMPRODUCT($N$28:$N$32,$K$28:$K$32/$K$33)} -> 215 | O33: =SUM(O28:O32) -> 21.5
C34: Accessories | D34: =O49 -> 2280 | E34: =D34/$G$15 -> 8.2014388 | G34: =E34/E$29 -> 0.37541031 | I34: Accessories | J34: Item Name | K34: Cons. / Pc | L34: UOM | M34: Rate-$ | N34: Rate-Pkr | O34: Cost
C35: Chemicals | D35: =O51 -> 25 | E35: =D35/$G$15 -> 0.089928058 | G35: =E35/E$29 -> 0.0041163411 | I35: Before Wash | J35: Zippers | K35: 1 | L35: Pcs | M35: 8.2014388 | N35: =M35*$G$16 -> 2280 | O35: =K35*N35 -> 2280
C36: Other Cost | D36: =O57 -> 0 | E36: =D36/$G$15 -> 0 | G36: =E36/E$29 -> 0 | J36: Thread | K36: 1 | L36: Pcs | N36: =M36*$G$16 -> 0 | O36: =K36*N36 -> 0
A37: =(D37*$J$13)/$J$11 -> 8.9340306 | C37: D Labor Cost | D37: ='CPM DATA'!J13/Model!$J$13*$J$11 -> 541.17415 | E37: =D37/$G$15 -> 1.9466696 | G37: =E37/E$29 -> 0.089106296 | J37: Labels | K37: 1 | L37: Pcs | N37: =M37*$G$16 -> 0 | O37: =K37*N37 -> 0
A38: =(D38*$J$13)/$J$11 -> 4.4846655 | C38: Utilities Cost | D38: =('CPM DATA'!J20+'CPM DATA'!J27)/Model!$J$13*$J$11 -> 271.65623 | E38: =D38/$G$15 -> 0.97718068 | G38: =E38/E$29 -> 0.044729188 | J38: Trims Mix Materials | K38: 1 | L38: Pcs | N38: =M38*$G$16 -> 0 | O38: =K38*N38 -> 0
C39: Leftover Factor | D39: =D15*SUM(D32:D38) -> 187.20361 | E39: =D39/$G$15 -> 0.67339428 | G39: =E39/E$29 -> 0.030823757 | O39: =K39*N39 -> 0
C40: Total Variable Cost | D40: =SUM(D32:D39) -> 4698.134 | E40: =SUM(E32:E39) -> 16.899763 | G40: =E40/E$29 -> 0.77356488 | O40: =K40*N40 -> 0
I41: After Wash | J41: Poly Bags | K41: 1 | L41: Pcs | N41: =M41*$G$16 -> 0 | O41: =K41*N41 -> 0
C42: CM/Pc | D42: =D29-D40 -> 1375.2208 | E42: =E29-E40 -> 4.9468374 | G42: =E42/E$29 -> 0.22643512 | J42: Tag | K42: 1 | L42: Pcs | N42: =M42*$G$16 -> 0 | O42: =K42*N42 -> 0
C43: CM/Minute | D43: =(D42*J13)/J11 -> 22.702978 | E43: =D43/G15*100 -> 8.1665388 | J43: Cartons | K43: 1 | L43: Pcs | N43: =M43*$G$16 -> 0 | O43: =K43*N43 -> 0
...

Sheet Master Grid
B2: Cutting | C2: BASIC | D2: SEMI FASHION | E2: FASHION | F2: HIGH FASHION | H2: =A3 -> HIGH FASHION | I2: Fabric | J2: BASIC | K2: SEMI FASHION | L2: FASHION | M2: HIGH FASHION
A3: =IF(Model!D9<=1.25,"BASIC",IF(B3<=1.55,"SEMI FASHION",IF(B3<=1.85,"FASHION","HIGH FASHION"))) -> HIGH FASHION | B3: SAM | C3: 2.3 | D3: 2.5 | E3: 2.75 | F3: 3 | H3: =Model!D10 -> <=500 | I3: <=500 | J3: 0.6 | K3: 0.65 | L3: 0.7 | M3: 0.75
H4: =H3 -> <=500 | I4: 501-1000 | J4: 0.5 | K4: 0.5 | L4: 0.5 | M4: 0.5
H5: =H4 -> <=500 | I5: 1001-2000 | J5: 0.5 | K5: 0.5 | L5: 0.5 | M5: 0.5
H6: =H5 -> <=500 | I6: 2001-3000 | J6: 0.5 | K6: 0.5 | L6: 0.5 | M6: 0.5
H7: =H6 -> <=500 | I7: 3001-4000 | J7: 0.5 | K7: 0.5 | L7: 0.5 | M7: 0.5
H8: =H7 -> <=500 | I8: 4001-5000 | J8: 0.5 | K8: 0.5 | L8: 0.5 | M8: 0.5
H9: =H8 -> <=500 | I9: 5001-10000 | J9: 0.4 | K9: 0.4 | L9: 0.4 | M9: 0.4
H10: =H9 -> <=500 | I10: 10001-25000 | J10: 0.4 | K10: 0.4 | L10: 0.4 | M10: 0.4
H11: =H10 -> <=500 | I11: >25000 | J11: 0.4 | K11: 0.4 | L11: 0.4 | M11: 0.4
I12: =H3 -> <=500 | J12: {=SUM(IF($I$3:$I$11=$I12,IF($H2='Master Grid'!J$2,'Master Grid'!J$3:J$11)))} -> 0 | K12: {=SUM(IF($I$3:$I$11=$I12,IF($H2='Master Grid'!K$2,'Master Grid'!K$3:K$11)))} -> 0 | L12: {=SUM(IF($I$3:$I$11=$I12,IF($H2='Master Grid'!L$2,'Master Grid'!L$3:L$11)))} -> 0 | M12: {=SUM(IF($I$3:$I$11=$I12,IF($H2='Master Grid'!M$2,'Master Grid'!M$3:M$11)))} -> 0.75
H13: =A3 -> HIGH FASHION | I13: Cutting | J13: BASIC | K13: SEMI FASHION | L13: FASHION | M13: HIGH FASHION
H14: =Model!D10 -> <=500 | I14: <=500 | J14: 0.3 | K14: 0.3 | L14: 0.3 | M14: 0.3
H15: =H14 -> <=500 | I15: 501-1000 | J15: 0.25 | K15: 0.25 | L15: 0.25 | M15: 0.25
H16: =H15 -> <=500 | I16: 1001-2000 | J16: 0.25 | K16: 0.25 | L16: 0.25 | M16: 0.25
H17: =H16 -> <=500 | I17: 2001-3000 | J17: 0.25 | K17: 0.25 | L17: 0.25 | M17: 0.25
H18: =H17 -> <=500 | I18: 3001-4000 | J18: 0.25 | K18: 0.25 | L18: 0.25 | M18: 0.25
H19: =H18 -> <=500 | I19: 4001-5000 | J19: 0.25 | K19: 0.25 | L19: 0.25 | M19: 0.25
H20: =H19 -> <=500 | I20: 5001-10000 | J20: 0.2 | K20: 0.2 | L20: 0.2 | M20: 0.2
H21: =H20 -> <=500 | I21: 10001-25000 | J21: 0.2 | K21: 0.2 | L21: 0.2 | M21: 0.2
H22: =H21 -> <=500 | I22: >25000 | J22: 0.2 | K22: 0.2 | L22: 0.2 | M22: 0.2
C23: =IF(Model!J11<='Master Grid'!C25,'Master Grid'!C24) -> FALSE | D23: =IF(AND(Model!J11>3),IF(Model!J11<='Master Grid'!D25,'Master Grid'!D24)) -> FALSE | E23: =IF(AND(Model!J11>5),IF(Model!J11<='Master Grid'!E25,'Master Grid'!E24)) -> FASHION | F23: =IF(AND(Model!J11>7),'Master Grid'!F24) -> HIGH FASHION | I23: =H14 -> <=500 | J23: {=SUM(IF($I$14:$I$22=$I23,IF($H13='Master Grid'!J$13,'Master Grid'!J$14:J$22)))} -> 0 | K23: {=SUM(IF($I$14:$I$22=$I23,IF($H13='Master Grid'!K$13,'Master Grid'!K$14:K$22)))} -> 0 | L23: {=SUM(IF($I$14:$I$22=$I23,IF($H13='Master Grid'!L$13,'Master Grid'!L$14:L$22)))} -> 0 | M23: {=SUM(IF($I$14:$I$22=$I23,IF($H13='Master Grid'!M$13,'Master Grid'!M$14:M$22)))} -> 0.3
B24: Sewing | C24: BASIC | D24: SEMI FASHION | E24: FASHION | F24: HIGH FASHION | H24: =A25 -> FASHION | I24: Sewing | J24: BASIC | K24: SEMI FASHION | L24: FASHION | M24: HIGH FASHION
A25: =IF(C23=C24,C24,IF(D23=D24,D24,IF(E23=E24,E24,IF(F23=F24,F24)))) -> FASHION | B25: Qty. | C25: 18 | D25: 23 | E25: 36 | F25: 61 | H25: =Model!D10 -> <=500 | I25: <=500 | J25: 1.5 | K25: 1.5 | L25: 1.5 | M25: 1.5 | S25: Dyeing
A26: =H25 -> <=500 | B26: <=500 | C26: 54 | D26: 50 | E26: 47 | F26: 45 | H26: =H25 -> <=500 | I26: 501-1000 | J26: 0.75 | K26: 1 | L26: 1 | M26: 1 | S26: EW/Biopolish
A27: =H26 -> <=500 | B27: 501-1000 | C27: 56 | D27: 52 | E27: 48 | F27: 46 | H27: =H26 -> <=500 | I27: 1001-2000 | J27: 0.75 | K27: 1 | L27: 1 | M27: 1 | S27: EW/Bleach
A28: =H27 -> <=500 | B28: 1001-2000 | C28: 58 | D28: 53 | E28: 50 | F28: 48 | H28: =H27 -> <=500 | I28: 2001-3000 | J28: 0.75 | K28: 0.75 | L28: 0.75 | M28: 0.75 | S28: EW/Caustic
A29: =H28 -> <=500 | B29: 2001-3000 | C29: 60 | D29: 55 | E29: 52 | F29: 50 | H29: =H28 -> <=500 | I29: 3001-4000 | J29: 0.65 | K29: 0.85 | L29: 0.85 | M29: 0.85 | S29: Stone Bleach
A30: =H29 -> <=500 | B30: 3001-4000 | C30: 62 | D30: 57 | E30: 54 | F30: 52 | H30: =H29 -> <=500 | I30: 4001-5000 | J30: 0.65 | K30: 0.85 | L30: 0.85 | M30: 0.85 | S30: Stone Caustic
A31: =H30 -> <=500 | B31: 4001-5000 | C31: 65 | D31: 59 | E31: 56 | F31: 54 | H31: =H30 -> <=500 | I31: 5001-10000 | J31: 0.5 | K31: 0.65 | L31: 0.75 | M31: 0.75 | S31: Stone Wash
A32: =H31 -> <=500 | B32: 5001-10000 | C32: 68 | D32: 62 | E32: 58 | F32: 56 | H32: =H31 -> <=500 | I32: 10001-25000 | J32: 0.5 | K32: 0.65 | L32: 0.75 | M32: 0.75 | S32: Pinky Random
A33: =H32 -> <=500 | B33: 10001-25000 | C33: 72 | D33: 65 | E33: 60 | F33: 58 | H33: =H32 -> <=500 | I33: >25000 | J33: 0.5 | K33: 0.65 | L33: 0.75 | M33: 0.75 | S33: Bleach Random
A34: =H33 -> <=500 | B34: >25000 | C34: 75 | D34: 66 | E34: 62 | F34: 60 | I34: =H25 -> <=500 | J34: {=SUM(IF($I$25:$I$33=$I34,IF($H24='Master Grid'!J$24,'Master Grid'!J$25:J$33)))} -> 0 | K34: {=SUM(IF($I$25:$I$33=$I34,IF($H24='Master Grid'!K$24,'Master Grid'!K$25:K$33)))} -> 0 | L34: {=SUM(IF($I$25:$I$33=$I34,IF($H24='Master Grid'!L$24,'Master Grid'!L$25:L$33)))} -> 1.5 | M34: {=SUM(IF($I$25:$I$33=$I34,IF($H24='Master Grid'!M$24,'Master Grid'!M$25:M$33)))} -> 0 | S34: Snow Random
S35: Rinse
C36: =IF(Model!$D11<='Master Grid'!C38,'Master Grid'!C37) -> FALSE | D36: =IF(AND(Model!$D11>3),IF(Model!D11<='Master Grid'!D38,'Master Grid'!D37)) -> FALSE | E36: =IF(AND(Model!$D11>5),IF(Model!D11<='Master Grid'!E38,'Master Grid'!E37)) -> FALSE | F36: =IF(AND(Model!$D11>7),'Master Grid'!F37) -> HIGH FASHION | S36: Softner
B37: GDP | C37: BASIC | D37: SEMI FASHION | E37: FASHION | F37: HIGH FASHION | I37: Finishing | J37: BASIC | K37: SEMI FASHION | L37: FASHION | M37: HIGH FASHION | S37: Silicon Ball
A38: =IF(C36=C37,C37,IF(D36=D37,D37,IF(E36=E37,E37,IF(F36=F37,F37)))) -> HIGH FASHION | B38: Qty. | C38: 1.01 | D38: 1.25 | E38: 2 | F38: 4 | H38: =A38 -> HIGH FASHION | I38: <=500 | J38: 0.5 | K38: 0.5 | L38: 0.5 | M38: 0.5
A39: =A26 -> <=500 | B39: <=500 | C39: 55 | D39: 52 | E39: 50 | F39: 48 | H39: =Model!D10 -> <=500 | I39: 501-1000 | J39: 0.5 | K39: 0.5 | L39: 0.5 | M39: 0.5
A40: =A27 -> <=500 | B40: 501-1000 | C40: 56 | D40: 55 | E40: 52 | F40: 50 | H40: =H39 -> <=500 | I40: 1001-2000 | J40: 0.25 | K40: 0.3 | L40: 0.3 | M40: 0.3
A41: =A28 -> <=500 | B41: 1001-2000 | C41: 58 | D41: 56 | E41: 54 | F41: 52 | H41: =H40 -> <=500 | I41: 2001-3000 | J41: 0.25 | K41: 0.3 | L41: 0.3 | M41: 0.3
...

Sheet Parameters
E3: CUT-TO-SHIP GRID | K3: REJECTION GRID | Q3: CUSTOMER WISE COMMISSION | T3: DATA AS %AGE OF SALES | W3: DIRECT LABOUR & FOH | Z3: ADMIN & SELLING | AC3: OTHER EXPENSES
B4: STYLE NAME | C4: SAM/PC | E4: Sewing | F4: BASIC | G4: SEMI FASHION | H4: FASHION | I4: HIGH FASHION | K4: Fabric | L4: BASIC | M4: SEMI FASHION | N4: FASHION | O4: HIGH FASHION | Q4: Customer | R4: Commission % | T4: DESCRIPTION | U4: %AGE OF SALES | W4: DESCRIPTION | X4: COST/SAM | Z4: DESCRIPTION | AA4: COST/SAM | AC4: DESCRIPTION | AD4: %AGE OF SALES | AF4: DELIVERY TERMS | AH4: PAYMENT TERMS | AJ4: WASH TYPE | AL4: STYLE CATEGORY | AN4: ORDER TYPE
B5: BASIC | C5: 1~18 | E5: Qty. | F5: 18 | G5: 23 | H5: 36 | I5: 61 | K5: <=500 | L5: 0.6 | M5: 0.65 | N5: 0.7 | O5: 0.75 | T5: Taxes | W5: Direct Labour | Z5: Salaries | AC5: Financial Charges | AF5: FOB | AH5: DA | AJ5: Softner | AL5: Top Ware | AN5: Denim
B6: SEMI FASHION | C6: 19~23 | E6: <=500 | F6: 54 | G6: 50 | H6: 47 | I6: 45 | K6: 501-1000 | L6: 0.5 | M6: 0.5 | N6: 0.5 | O6: 0.5 | T6: EDS | W6: Utilities Cost | Z6: FOH | AC6: Taxation | AF6: CIF | AH6: LC 60 DAYS | AJ6: Soft Wash | AL6: Boy's Pant | AN6: Non-Denim
B7: FASHION | C7: 24~36 | E7: 501-1000 | F7: 56 | G7: 52 | H7: 48 | I7: 46 | K7: 1001-2000 | L7: 0.5 | M7: 0.5 | N7: 0.5 | O7: 0.5 | T7: Bank Charges | W7: Manufacturing FOH | Z7: Inland/Export freight | AF7: CIR | AH7: ADVANCE | AJ7: Rinse | AL7: Girls Pant
B8: HIGH FASHION | C8: >37 | E8: 1001-2000 | F8: 58 | G8: 53 | H8: 50 | I8: 48 | K8: 2001-3000 | L8: 0.5 | M8: 0.5 | N8: 0.5 | O8: 0.5 | T8: Rebate | W8: Depreciation | AF8: etc. | AH8: etc. | AJ8: etc. | AL8: Shirts
E9: 2001-3000 | F9: 60 | G9: 55 | H9: 52 | I9: 50 | K9: 3001-4000 | L9: 0.5 | M9: 0.5 | N9: 0.5 | O9: 0.5 | T9: Exchange Rate
E10: 3001-4000 | F10: 62 | G10: 57 | H10: 54 | I10: 52 | K10: 4001-5000 | L10: 0.5 | M10: 0.5 | N10: 0.5 | O10: 0.5
E11: 4001-5000 | F11: 65 | G11: 59 | H11: 56 | I11: 54 | K11: 5001-10000 | L11: 0.4 | M11: 0.4 | N11: 0.4 | O11: 0.4
E12: 5001-10000 | F12: 68 | G12: 62 | H12: 58 | I12: 56 | K12: 10001-25000 | L12: 0.4 | M12: 0.4 | N12: 0.4 | O12: 0.4
E13: 10001-25000 | F13: 72 | G13: 65 | H13: 60 | I13: 58 | K13: >25000 | L13: 0.4 | M13: 0.4 | N13: 0.4 | O13: 0.4
E14: >25000 | F14: 75 | G14: 66 | H14: 62 | I14: 60 | K14: <=500 | L14: 0 | M14: 0 | N14: 0 | O14: 0.75
K15: Cutting | L15: BASIC | M15: SEMI FASHION | N15: FASHION | O15: HIGH FASHION
K16: <=500 | L16: 0.3 | M16: 0.3 | N16: 0.3 | O16: 0.3
K17: 501-1000 | L17: 0.25 | M17: 0.25 | N17: 0.25 | O17: 0.25
K18: 1001-2000 | L18: 0.25 | M18: 0.25 | N18: 0.25 | O18: 0.25
K19: 2001-3000 | L19: 0.25 | M19: 0.25 | N19: 0.25 | O19: 0.25
K20: 3001-4000 | L20: 0.25 | M20: 0.25 | N20: 0.25 | O20: 0.25
K21: 4001-5000 | L21: 0.25 | M21: 0.25 | N21: 0.25 | O21: 0.25
K22: 5001-10000 | L22: 0.2 | M22: 0.2 | N22: 0.2 | O22: 0.2
K23: 10001-25000 | L23: 0.2 | M23: 0.2 | N23: 0.2 | O23: 0.2
K24: >25000 | L24: 0.2 | M24: 0.2 | N24: 0.2 | O24: 0.2
K25: <=500 | L25: 0 | M25: 0 | N25: 0 | O25: 0.3
K26: Sewing | L26: BASIC | M26: SEMI FASHION | N26: FASHION | O26: HIGH FASHION
K27: <=500 | L27: 1.5 | M27: 1.5 | N27: 1.5 | O27: 1.5
K28: 501-1000 | L28: 0.75 | M28: 1 | N28: 1 | O28: 1
K29: 1001-2000 | L29: 0.75 | M29: 1 | N29: 1 | O29: 1
K30: 2001-3000 | L30: 0.75 | M30: 0.75 | N30: 0.75 | O30: 0.75
K31: 3001-4000 | L31: 0.65 | M31: 0.85 | N31: 0.85 | O31: 0.85
K32: 4001-5000 | L32: 0.65 | M32: 0.85 | N32: 0.85 | O32: 0.85
K33: 5001-10000 | L33: 0.5 | M33: 0.65 | N33: 0.75 | O33: 0.75
K34: 10001-25000 | L34: 0.5 | M34: 0.65 | N34: 0.75 | O34: 0.75
K35: >25000 | L35: 0.5 | M35: 0.65 | N35: 0.75 | O35: 0.75
K36: <=500 | L36: 0 | M36: 0 | N36: 1.5 | O36: 0
K39: Finishing | L39: BASIC | M39: SEMI FASHION | N39: FASHION | O39: HIGH FASHION
K40: <=500 | L40: 0.5 | M40: 0.5 | N40: 0.5 | O40: 0.5
K41: 501-1000 | L41: 0.5 | M41: 0.5 | N41: 0.5 | O41: 0.5
K42: 1001-2000 | L42: 0.25 | M42: 0.3 | N42: 0.3 | O42: 0.3
K43: 2001-3000 | L43: 0.25 | M43: 0.3 | N43: 0.3 | O43: 0.3
K44: 3001-4000 | L44: 0.25 | M44: 0.3 | N44: 0.3 | O44: 0.3
...
